Workbook

Sheet Notas
A1: EVPI Quito: diferencia en diferencias por administración zonal (2023-2024 vs. 2025-2026)
A3: Qué se estima
A4: Para cada indicador y cada administración zonal (AZ), DiD = (media 2025 en la AZ − media 2023 en la AZ) − (media 2025 en el resto del DMQ − media 2023 en el resto).
A5: Equivale al coeficiente de la interacción en y = a + b·AZ + c·Post + DiD·(AZ×Post), estimado por MCP con pesos = peso_az_estrato.
A6: Todos los indicadores son proporciones (0/1), así que el DiD se expresa en puntos porcentuales (pp). Un DiD positivo significa que el indicador subió más (o bajó menos) en la AZ que en el resto del DMQ.
A7: No se etiqueta "mejoró/empeoró": el signo describe la dirección del indicador. Los colores (azul/naranja) indican solo la dirección.
A9: Inferencia
A10: Errores estándar robustos HC1 con pesos (equivalente a regress [pw], robust en Stata). No se corrige por conglomerados ni estratos del diseño muestral: los IC son probablemente algo estrechos.
A11: Valor p con aproximación normal. q_BH: valor q de Benjamini-Hochberg entre las 10 AZ de cada indicador (hoja Detalle), útil porque se hacen 560 contrastes.
A12: Las 10 comparaciones "AZ vs. resto" de un mismo indicador no son independientes: el resto de cada AZ contiene a las otras nueve.
A14: Construcción de indicadores
A15: Percepción (bloque A): % "Muy inseguro + Inseguro"; excluye "No aplica". PSC_10 (buses) se excluye porque no es comparable entre olas.
... A35: Fuente: EVPI 2023-2024 y 2025-2026, OMSCGR (archivo EVPI_2024_2026_VF_1.xlsx). Cálculos propios en Python (statsmodels).

Sheet Resumen
A1: DiD (pp) por administración zonal vs. resto del DMQ, 2023-2024 → 2025-2026
A2: Negrita con borde = p<0,05. Azul: el indicador bajó más (o subió menos) que en el resto; naranja: subió más (o bajó menos). Sin valoración normativa.
A4: Bloque | B4: Indicador | C4: Calderón | D4: Choco Andino | E4: Eloy Alfaro | F4: Eugenio Espejo | G4: La Delicia | H4: La Mariscal | I4: Los Chillos | J4: Manuela Sáenz | K4: Quitumbe | L4: Tumbaco | N4: p · Calderón | O4: p · Choco Andino | P4: p · Eloy Alfaro | Q4: p · Eugenio Espejo | R4: p · La Delicia | S4: p · La Mariscal | T4: p · Los Chillos | U4: p · Manuela Sáenz | V4: p · Quitumbe | W4: p · Tumbaco
A5: A. Percepción de inseguridad
A6: PSC_1 | B6: Inseguro: Alrededor de su casa | C6: =Calderón!K6 -> -7.0605035 | D6: ='Choco Andino'!K6 -> -0.6164116 | E6: ='Eloy Alfaro'!K6 -> 0.72685117 | F6: ='Eugenio Espejo'!K6 -> -6.9621469 | G6: ='La Delicia'!K6 -> -9.2638498 | H6: ='La Mariscal'!K6 -> -10.394678 | I6: ='Los Chillos'!K6 -> 29.316178 | J6: ='Manuela Sáenz'!K6 -> 2.4232325 | K6: =Quitumbe!K6 -> -4.7393197 | L6: =Tumbaco!K6 -> 3.713087 | N6: =Calderón!O6 -> 0.060876479 | O6: ='Choco Andino'!O6 -> 0.90858457 | P6: ='Eloy Alfaro'!O6 -> 0.85233414 | Q6: ='Eugenio Espejo'!O6 -> 0.120583 | R6: ='La Delicia'!O6 -> 0.02817088 | S6: ='La Mariscal'!O6 -> 0.06213025 | T6: ='Los Chillos'!O6 -> 3.2211789e-10 | U6: ='Manuela Sáenz'!O6 -> 0.54380629 | V6: =Quitumbe!O6 -> 0.275708 | W6: =Tumbaco!O6 -> 0.34555306
A7: PSC_2 | B7: Inseguro: En su barrio | C7: =Calderón!K7 -> -2.5622867 | D7: ='Choco Andino'!K7 -> 0.96405189 | E7: ='Eloy Alfaro'!K7 -> -0.50266756 | F7: ='Eugenio Espejo'!K7 -> -3.1786121 | G7: ='La Delicia'!K7 -> -6.285092 | H7: ='La Mariscal'!K7 -> -14.218424 | I7: ='Los Chillos'!K7 -> 25.260113 | J7: ='Manuela Sáenz'!K7 -> -5.470529 | K7: =Quitumbe!K7 -> -5.0700655 | L7: =Tumbaco!K7 -> 7.0886198 | N7: =Calderón!O7 -> 0.46407796 | O7: ='Choco Andino'!O7 -> 0.86269857 | P7: ='Eloy Alfaro'!O7 -> 0.89092722 | Q7: ='Eugenio Espejo'!O7 -> 0.4759885 | R7: ='La Delicia'!O7 -> 0.11696099 | S7: ='La Mariscal'!O7 -> 0.00468874 | T7: ='Los Chillos'!O7 -> 9.836704e-07 | U7: ='Manuela Sáenz'!O7 -> 0.15093165 | V7: =Quitumbe!O7 -> 0.23193202 | W7: =Tumbaco!O7 -> 0.067155169
A8: PSC_4 | B8: Inseguro: Cerca de centros educativos | C8: =Calderón!K8 -> 1.5406063 | D8: ='Choco Andino'!K8 -> -3.8260806 | E8: ='Eloy Alfaro'!K8 -> 0.14453204 | F8: ='Eugenio Espejo'!K8 -> -4.2972947 | G8: ='La Delicia'!K8 -> -11.157653 | H8: ='La Mariscal'!K8 -> -0.099893807 | I8: ='Los Chillos'!K8 -> 25.745542 | J8: ='Manuela Sáenz'!K8 -> 6.1776317 | K8: =Quitumbe!K8 -> -16.082573 | L8: =Tumbaco!K8 -> 11.689963 | N8: =Calderón!O8 -> 0.69716678 | O8: ='Choco Andino'!O8 -> 0.524085 | P8: ='Eloy Alfaro'!O8 -> 0.9719886 | Q8: ='Eugenio Espejo'!O8 -> 0.36759915 | R8: ='La Delicia'!O8 -> 0.012743111 | S8: ='La Mariscal'!O8 -> 0.98618141 | T8: ='Los Chillos'!O8 -> 3.2407807e-06 | U8: ='Manuela Sáenz'!O8 -> 0.14927593 | V8: =Quitumbe!O8 -> 0.00012847048 | W8: =Tumbaco!O8 -> 0.0053129869
A9: PSC_5 | B9: Inseguro: Mercados y ferias | C9: =Calderón!K9 -> -6.7890444 | D9: ='Choco Andino'!K9 -> 2.6414146 | E9: ='Eloy Alfaro'!K9 -> -1.71051 | F9: ='Eugenio Espejo'!K9 -> -6.2944271 | G9: ='La Delicia'!K9 -> -3.0101267 | H9: ='La Mariscal'!K9 -> 0.27376835 | I9: ='Los Chillos'!K9 -> 5.6994622 | J9: ='Manuela Sáenz'!K9 -> 7.4962147 | K9: =Quitumbe!K9 -> -2.1782668 | L9: =Tumbaco!K9 -> 11.706419 | N9: =Calderón!O9 -> 0.053180443 | O9: ='Choco Andino'!O9 -> 0.69844673 | P9: ='Eloy Alfaro'!O9 -> 0.62190428 | Q9: ='Eugenio Espejo'!O9 -> 0.18485696 | R9: ='La Delicia'!O9 -> 0.48860169 | S9: ='La Mariscal'!O9 -> 0.9562066 | T9: ='Los Chillos'!O9 -> 0.14305942 | U9: ='Manuela Sáenz'!O9 -> 0.026230679 | V9: =Quitumbe!O9 -> 0.54198872 | W9: =Tumbaco!O9 -> 0.001355679
A10: PSC_6 | B10: Inseguro: Cajeros en vía pública | C10: =Calderón!K10 -> -3.9798866 | D10: ='Choco Andino'!K10 -> -8.0024667 | E10: ='Eloy Alfaro'!K10 -> -1.72421 | F10: ='Eugenio Espejo'!K10 -> 3.8783241 | G10: ='La Delicia'!K10 -> -0.46826442 | H10: ='La Mariscal'!K10 -> -2.2516766 | I10: ='Los Chillos'!K10 -> 10.969601 | J10: ='Manuela Sáenz'!K10 -> -3.4597414 | K10: =Quitumbe!K10 -> -5.5929555 | L10: =Tumbaco!K10 -> 3.6240068 | N10: =Calderón!O10 -> 0.27624956 | O10: ='Choco Andino'!O10 -> 0.28420142 | P10: ='Eloy Alfaro'!O10 -> 0.63629703 | Q10: ='Eugenio Espejo'!O10 -> 0.41174302 | R10: ='La Delicia'!O10 -> 0.91546025 | S10: ='La Mariscal'!O10 -> 0.64660486 | T10: ='Los Chillos'!O10 -> 0.0036373028 | U10: ='Manuela Sáenz'!O10 -> 0.31167436 | V10: =Quitumbe!O10 -> 0.10705788 | W10: =Tumbaco!O10 -> 0.27471519
A11: PSC_7 | B11: Inseguro: Espacios públicos de la ciudad | C11: =Calderón!K11 -> 0.9420992 | D11: ='Choco Andino'!K11 -> -1.468891 | E11: ='Eloy Alfaro'!K11 -> -0.64024005 | F11: ='Eugenio Espejo'!K11 -> -2.0969778 | G11: ='La Delicia'!K11 -> -2.8667792 | H11: ='La Mariscal'!K11 -> -8.7668851 | I11: ='Los Chillos'!K11 -> 5.3908115 | J11: ='Manuela Sáenz'!K11 -> -2.7113515 | K11: =Quitumbe!K11 -> -4.1469034 | L11: =Tumbaco!K11 -> 13.553436 | N11: =Calderón!O11 -> 0.7787773 | O11: ='Choco Andino'!O11 -> 0.81202081 | P11: ='Eloy Alfaro'!O11 -> 0.83188232 | Q11: ='Eugenio Espejo'!O11 -> 0.61534929 | R11: ='La Delicia'!O11 -> 0.38876565 | S11: ='La Mariscal'!O11 -> 0.074283537 | T11: ='Los Chillos'!O11 -> 0.13780331 | U11: ='Manuela Sáenz'!O11 -> 0.35796982 | V11: =Quitumbe!O11 -> 0.2004472 | W11: =Tumbaco!O11 -> 2.5224133e-05
A12: PSC_8 | B12: Inseguro: Metro de Quito | C12: =Calderón!K12 -> -7.8302994 | D12: ='Choco Andino'!K12 -> -11.739828 | E12: ='Eloy Alfaro'!K12 -> 4.1855606 | F12: ='Eugenio Espejo'!K12 -> -1.273513 | G12: ='La Delicia'!K12 -> 2.8699899 | H12: ='La Mariscal'!K12 -> -11.966673 | I12: ='Los Chillos'!K12 -> 0.51090775 | J12: ='Manuela Sáenz'!K12 -> -5.6426368 | K12: =Quitumbe!K12 -> 8.3591532 | L12: =Tumbaco!K12 -> 15.001522 | N12: =Calderón!O12 -> 0.05681009 | O12: ='Choco Andino'!O12 -> 0.14917293 | P12: ='Eloy Alfaro'!O12 -> 0.19751115 | Q12: ='Eugenio Espejo'!O12 -> 0.75862821 | R12: ='La Delicia'!O12 -> 0.50861878 | S12: ='La Mariscal'!O12 -> 0.022498949 | T12: ='Los Chillos'!O12 -> 0.90984981 | U12: ='Manuela Sáenz'!O12 -> 0.14674271 | V12: =Quitumbe!O12 -> 0.033916208 | W12: =Tumbaco!O12 -> 0.0012583943
A13: PSC_9 | B13: Inseguro: Trole, Ecovía, corredores | C13: =Calderón!K13 -> -3.9975626 | D13: ='Choco Andino'!K13 -> 21.100649 | E13: ='Eloy Alfaro'!K13 -> -13.484234 | F13: ='Eugenio Espejo'!K13 -> 3.6699587 | G13: ='La Delicia'!K13 -> 1.8785233 | H13: ='La Mariscal'!K13 -> -2.9357133 | I13: ='Los Chillos'!K13 -> 11.188881 | J13: ='Manuela Sáenz'!K13 -> -2.0597364 | K13: =Quitumbe!K13 -> 1.2491972 | L13: =Tumbaco!K13 -> 11.251772 | N13: =Calderón!O13 -> 0.15508319 | O13: ='Choco Andino'!O13 -> 0.00044295971 | P13: ='Eloy Alfaro'!O13 -> 1.7180714e-05 | Q13: ='Eugenio Espejo'!O13 -> 0.30895102 | R13: ='La Delicia'!O13 -> 0.51861389 | S13: ='La Mariscal'!O13 -> 0.42332292 | T13: ='Los Chillos'!O13 -> 0.0015307435 | U13: ='Manuela Sáenz'!O13 -> 0.50116996 | V13: =Quitumbe!O13 -> 0.7013284 | W13: =Tumbaco!O13 -> 0.00034452699
A14: PSC_11 | B14: Inseguro: Taxis amarillos | C14: =Calderón!K14 -> -6.0586596 | D14: ='Choco Andino'!K14 -> 0.17260022 | E14: ='Eloy Alfaro'!K14 -> -5.838113 | F14: ='Eugenio Espejo'!K14 -> 1.6406935 | G14: ='La Delicia'!K14 -> -6.2131383 | H14: ='La Mariscal'!K14 -> -9.6473978 | I14: ='Los Chillos'!K14 -> 7.5222869 | J14: ='Manuela Sáenz'!K14 -> 1.9056714 | K14: =Quitumbe!K14 -> 2.5249463 | L14: =Tumbaco!K14 -> 12.670886 | N14: =Calderón!O14 -> 0.12753108 | O14: ='Choco Andino'!O14 -> 0.98003488 | P14: ='Eloy Alfaro'!O14 -> 0.13017642 | Q14: ='Eugenio Espejo'!O14 -> 0.72017513 | R14: ='La Delicia'!O14 -> 0.14308195 | S14: ='La Mariscal'!O14 -> 0.081178489 | T14: ='Los Chillos'!O14 -> 0.13203725 | U14: ='Manuela Sáenz'!O14 -> 0.65489745 | V14: =Quitumbe!O14 -> 0.61308127 | W14: =Tumbaco!O14 -> 0.0022083317
A15: PSC_12 | B15: Inseguro: Transporte por aplicaciones | C15: =Calderón!K15 -> -7.0928404 | D15: ='Choco Andino'!K15 -> -10.876536 | E15: ='Eloy Alfaro'!K15 -> -5.2131664 | F15: ='Eugenio Espejo'!K15 -> 4.0260622 | G15: ='La Delicia'!K15 -> 4.5058667 | H15: ='La Mariscal'!K15 -> -11.689821 | I15: ='Los Chillos'!K15 -> -2.0748227 | J15: ='Manuela Sáenz'!K15 -> -1.4465784 | K15: =Quitumbe!K15 -> 7.6765582 | L15: =Tumbaco!K15 -> 6.6157727 | N15: =Calderón!O15 -> 0.10953872 | O15: ='Choco Andino'!O15 -> 0.16741562 | P15: ='Eloy Alfaro'!O15 -> 0.23139199 | Q15: ='Eugenio Espejo'!O15 -> 0.42339632 | R15: ='La Delicia'!O15 -> 0.36286167 | S15: ='La Mariscal'!O15 -> 0.038497992 | T15: ='Los Chillos'!O15 -> 0.72294522 | U15: ='Manuela Sáenz'!O15 -> 0.7509748 | V15: =Quitumbe!O15 -> 0.15216751 | W15: =Tumbaco!O15 -> 0.13550074
A16: PSC_13 | B16: Inseguro: Espectáculos públicos | C16: =Calderón!K16 -> -1.6538753 | D16: ='Choco Andino'!K16 -> 9.3274662 | E16: ='Eloy Alfaro'!K16 -> -1.0705723 | F16: ='Eugenio Espejo'!K16 -> -4.5596966 | G16: ='La Delicia'!K16 -> 8.2323016 | H16: ='La Mariscal'!K16 -> -13.31936 | I16: ='Los Chillos'!K16 -> 11.192107 | J16: ='Manuela Sáenz'!K16 -> -5.3075528 | K16: =Quitumbe!K16 -> -9.1973317 | L16: =Tumbaco!K16 -> 12.734067 | N16: =Calderón!O16 -> 0.69413183 | O16: ='Choco Andino'!O16 -> 0.20631422 | P16: ='Eloy Alfaro'!O16 -> 0.79445582 | Q16: ='Eugenio Espejo'!O16 -> 0.36648595 | R16: ='La Delicia'!O16 -> 0.10271276 | S16: ='La Mariscal'!O16 -> 0.022986863 | T16: ='Los Chillos'!O16 -> 0.012590741 | U16: ='Manuela Sáenz'!O16 -> 0.17371806 | V16: =Quitumbe!O16 -> 0.062678848 | W16: =Tumbaco!O16 -> 0.0018024023
A17: PSC_14 | B17: Inseguro: Caminando solo/a en el barrio de día | C17: =Calderón!K17 -> -6.5455782 | D17: ='Choco Andino'!K17 -> 0.92651335 | E17: ='Eloy Alfaro'!K17 -> -4.1889551 | F17: ='Eugenio Espejo'!K17 -> -4.4584027 | G17: ='La Delicia'!K17 -> -2.3338472 | H17: ='La Mariscal'!K17 -> -6.1184866 | I17: ='Los Chillos'!K17 -> 15.650194 | J17: ='Manuela Sáenz'!K17 -> -4.7554066 | K17: =Quitumbe!K17 -> 6.9340056 | L17: =Tumbaco!K17 -> 1.8557821 | N17: =Calderón!O17 -> 0.10428858 | O17: ='Choco Andino'!O17 -> 0.82924732 | P17: ='Eloy Alfaro'!O17 -> 0.29638242 | Q17: ='Eugenio Espejo'!O17 -> 0.31816177 | R17: ='La Delicia'!O17 -> 0.59154273 | S17: ='La Mariscal'!O17 -> 0.25052144 | T17: ='Los Chillos'!O17 -> 0.00074198318 | U17: ='Manuela Sáenz'!O17 -> 0.23142908 | V17: =Quitumbe!O17 -> 0.14230051 | W17: =Tumbaco!O17 -> 0.64060006
A18: PSC_15 | B18: Inseguro: Caminando solo/a en el barrio de noche | C18: =Calderón!K18 -> -0.98284736 | D18: ='Choco Andino'!K18 -> -4.3039657 | E18: ='Eloy Alfaro'!K18 -> -2.9174615 | F18: ='Eugenio Espejo'!K18 -> -4.6039204 | G18: ='La Delicia'!K18 -> -3.409113 | H18: ='La Mariscal'!K18 -> -1.1870655 | I18: ='Los Chillos'!K18 -> 15.866311 | J18: ='Manuela Sáenz'!K18 -> -4.0195062 | K18: =Quitumbe!K18 -> -6.086222 | L18: =Tumbaco!K18 -> 14.020138 | N18: =Calderón!O18 -> 0.68004789 | O18: ='Choco Andino'!O18 -> 0.48095048 | P18: ='Eloy Alfaro'!O18 -> 0.32751189 | Q18: ='Eugenio Espejo'!O18 -> 0.24115605 | R18: ='La Delicia'!O18 -> 0.24902686 | S18: ='La Mariscal'!O18 -> 0.75280084 | T18: ='Los Chillos'!O18 -> 1.9301902e-06 | U18: ='Manuela Sáenz'!O18 -> 0.12915914 | V18: =Quitumbe!O18 -> 0.019202069 | W18: =Tumbaco!O18 -> 2.6269429e-06
A19: B. Evolución percibida de la delincuencia
A20: PSC_16 | B20: Delincuencia aumentó en su barrio | C20: =Calderón!K20 -> -0.26845215 | D20: ='Choco Andino'!K20 -> 10.517586 | E20: ='Eloy Alfaro'!K20 -> -8.7995251 | F20: ='Eugenio Espejo'!K20 -> 2.4222344 | G20: ='La Delicia'!K20 -> -6.6802582 | H20: ='La Mariscal'!K20 -> -6.261804 | I20: ='Los Chillos'!K20 -> 15.497275 | J20: ='Manuela Sáenz'!K20 -> 4.9777614 | K20: =Quitumbe!K20 -> -8.1503639 | L20: =Tumbaco!K20 -> 11.671601 | N20: =Calderón!O20 -> 0.94396505 | O20: ='Choco Andino'!O20 -> 0.06463264 | P20: ='Eloy Alfaro'!O20 -> 0.024036806 | Q20: ='Eugenio Espejo'!O20 -> 0.59388113 | R20: ='La Delicia'!O20 -> 0.11714891 | S20: ='La Mariscal'!O20 -> 0.23835025 | T20: ='Los Chillos'!O20 -> 0.0035212213 | U20: ='Manuela Sáenz'!O20 -> 0.21983126 | V20: =Quitumbe!O20 -> 0.066719566 | W20: =Tumbaco!O20 -> 0.003233572
A21: PSC_17 | B21: Delincuencia aumentó en Quito | C21: =Calderón!K21 -> 3.7684179 | D21: ='Choco Andino'!K21 -> 2.4241185 | E21: ='Eloy Alfaro'!K21 -> -5.0087285 | F21: ='Eugenio Espejo'!K21 -> -1.20759 | G21: ='La Delicia'!K21 -> -2.962634 | H21: ='La Mariscal'!K21 -> -3.0486372 | I21: ='Los Chillos'!K21 -> 7.6853589 | J21: ='Manuela Sáenz'!K21 -> 1.0531266 | K21: =Quitumbe!K21 -> -0.078178399 | L21: =Tumbaco!K21 -> 5.81596 | N21: =Calderón!O21 -> 0.080827531 | O21: ='Choco Andino'!O21 -> 0.37949014 | P21: ='Eloy Alfaro'!O21 -> 0.042352507 | Q21: ='Eugenio Espejo'!O21 -> 0.69201401 | R21: ='La Delicia'!O21 -> 0.24531803 | S21: ='La Mariscal'!O21 -> 0.30285915 | T21: ='Los Chillos'!O21 -> 0.24072244 | U21: ='Manuela Sáenz'!O21 -> 0.65154166 | V21: =Quitumbe!O21 -> 0.97742638 | W21: =Tumbaco!O21 -> 0.021220323
A22: PSC_18 | B22: Delincuencia aumentó en el país | C22: =Calderón!K22 -> 5.3055648 | D22: ='Choco Andino'!K22 -> -1.0764508 | E22: ='Eloy Alfaro'!K22 -> -6.2683682 | F22: ='Eugenio Espejo'!K22 -> 0.39168396 | G22: ='La Delicia'!K22 -> -0.19427662 | H22: ='La Mariscal'!K22 -> 2.4232625 | I22: ='Los Chillos'!K22 -> 1.0836233 | J22: ='Manuela Sáenz'!K22 -> -0.63043338 | K22: =Quitumbe!K22 -> -1.0586526 | L22: =Tumbaco!K22 -> 6.5289624 | N22: =Calderón!O22 -> 0.0052910953 | O22: ='Choco Andino'!O22 -> 0.63505596 | P22: ='Eloy Alfaro'!O22 -> 0.00036236509 | Q22: ='Eugenio Espejo'!O22 -> 0.83749396 | R22: ='La Delicia'!O22 -> 0.91882457 | S22: ='La Mariscal'!O22 -> 0.29503614 | T22: ='Los Chillos'!O22 -> 0.52931843 | U22: ='Manuela Sáenz'!O22 -> 0.70815639 | V22: =Quitumbe!O22 -> 0.65556141 | W22: =Tumbaco!O22 -> 0.0013448721
A23: C. Problemas percibidos en el barrio
A24: CC_1 | B24: Peleas o riñas | C24: =Calderón!K24 -> -14.213922 | D24: ='Choco Andino'!K24 -> 2.8550937 | E24: ='Eloy Alfaro'!K24 -> -2.0388945 | F24: ='Eugenio Espejo'!K24 -> -3.2353109 | G24: ='La Delicia'!K24 -> -7.9701464 | H24: ='La Mariscal'!K24 -> -7.324615 | I24: ='Los Chillos'!K24 -> 18.511283 | J24: ='Manuela Sáenz'!K24 -> 8.761957 | K24: =Quitumbe!K24 -> -11.668015 | L24: =Tumbaco!K24 -> 19.693483 | N24: =Calderón!O24 -> 0.00033617102 | O24: ='Choco Andino'!O24 -> 0.63309209 | P24: ='Eloy Alfaro'!O24 -> 0.59724199 | Q24: ='Eugenio Espejo'!O24 -> 0.47290306 | R24: ='La Delicia'!O24 -> 0.066516495 | S24: ='La Mariscal'!O24 -> 0.17340263 | T24: ='Los Chillos'!O24 -> 5.0228259e-05 | U24: ='Manuela Sáenz'!O24 -> 0.027734765 | V24: =Quitumbe!O24 -> 0.0091172205 | W24: =Tumbaco!O24 -> 4.7210909e-07
A25: CC_2 | B25: Pandillas o grupos delictivos | C25: =Calderón!K25 -> -21.694822 | D25: ='Choco Andino'!K25 -> 10.527091 | E25: ='Eloy Alfaro'!K25 -> 1.9152681 | F25: ='Eugenio Espejo'!K25 -> -1.8528889 | G25: ='La Delicia'!K25 -> -1.7076293 | H25: ='La Mariscal'!K25 -> -10.498435 | I25: ='Los Chillos'!K25 -> 4.9086126 | J25: ='Manuela Sáenz'!K25 -> 7.1021012 | K25: =Quitumbe!K25 -> -4.8752986 | L25: =Tumbaco!K25 -> 18.668221 | N25: =Calderón!O25 -> 9.5206972e-08 | O25: ='Choco Andino'!O25 -> 0.030910992 | P25: ='Eloy Alfaro'!O25 -> 0.63464131 | Q25: ='Eugenio Espejo'!O25 -> 0.64419961 | R25: ='La Delicia'!O25 -> 0.70645988 | S25: ='La Mariscal'!O25 -> 0.060508693 | T25: ='Los Chillos'!O25 -> 0.41401959 | U25: ='Manuela Sáenz'!O25 -> 0.066065282 | V25: =Quitumbe!O25 -> 0.31215299 | W25: =Tumbaco!O25 -> 2.4479804e-06
A26: CC_3 | B26: Consumo de alcohol en espacio público | C26: =Calderón!K26 -> -11.202902 | D26: ='Choco Andino'!K26 -> 2.8172889 | E26: ='Eloy Alfaro'!K26 -> -3.2678232 | F26: ='Eugenio Espejo'!K26 -> -5.6956936 | G26: ='La Delicia'!K26 -> 6.4991301 | H26: ='La Mariscal'!K26 -> 0.69109727 | I26: ='Los Chillos'!K26 -> 1.1796438 | J26: ='Manuela Sáenz'!K26 -> 7.7004803 | K26: =Quitumbe!K26 -> -9.1446575 | L26: =Tumbaco!K26 -> 21.339475 | N26: =Calderón!O26 -> 0.00066221199 | O26: ='Choco Andino'!O26 -> 0.5988588 | P26: ='Eloy Alfaro'!O26 -> 0.33285491 | Q26: ='Eugenio Espejo'!O26 -> 0.19050002 | R26: ='La Delicia'!O26 -> 0.073503662 | S26: ='La Mariscal'!O26 -> 0.89776124 | T26: ='Los Chillos'!O26 -> 0.77634701 | U26: ='Manuela Sáenz'!O26 -> 0.039543959 | V26: =Quitumbe!O26 -> 0.0094848892 | W26: =Tumbaco!O26 -> 5.4048779e-09
A27: CC_4 | B27: Venta clandestina de alcohol | C27: =Calderón!K27 -> -8.0887891 | D27: ='Choco Andino'!K27 -> 3.3958854 | E27: ='Eloy Alfaro'!K27 -> -3.2880617 | F27: ='Eugenio Espejo'!K27 -> 2.8550284 | G27: ='La Delicia'!K27 -> -1.6906584 | H27: ='La Mariscal'!K27 -> -10.180313 | I27: ='Los Chillos'!K27 -> 7.3158797 | J27: ='Manuela Sáenz'!K27 -> 7.4805936 | K27: =Quitumbe!K27 -> -16.278581 | L27: =Tumbaco!K27 -> 21.005972 | N27: =Calderón!O27 -> 0.051973096 | O27: ='Choco Andino'!O27 -> 0.58514724 | P27: ='Eloy Alfaro'!O27 -> 0.42582071 | Q27: ='Eugenio Espejo'!O27 -> 0.46954772 | R27: ='La Delicia'!O27 -> 0.71295324 | S27: ='La Mariscal'!O27 -> 0.071362909 | T27: ='Los Chillos'!O27 -> 0.10368921 | U27: ='Manuela Sáenz'!O27 -> 0.068979626 | V27: =Quitumbe!O27 -> 0.00056365196 | W27: =Tumbaco!O27 -> 2.5120655e-08
A28: CC_5 | B28: Consumo de drogas en espacio público | C28: =Calderón!K28 -> 0.22919144 | D28: ='Choco Andino'!K28 -> 10.874473 | E28: ='Eloy Alfaro'!K28 -> -1.8611165 | F28: ='Eugenio Espejo'!K28 -> -6.537693 | G28: ='La Delicia'!K28 -> 4.1087752 | H28: ='La Mariscal'!K28 -> -7.4004666 | I28: ='Los Chillos'!K28 -> -3.4177075 | J28: ='Manuela Sáenz'!K28 -> 6.9501007 | K28: =Quitumbe!K28 -> -19.063462 | L28: =Tumbaco!K28 -> 24.335694 | N28: =Calderón!O28 -> 0.95581492 | O28: ='Choco Andino'!O28 -> 0.058561459 | P28: ='Eloy Alfaro'!O28 -> 0.64864293 | Q28: ='Eugenio Espejo'!O28 -> 0.14740759 | R28: ='La Delicia'!O28 -> 0.35859731 | S28: ='La Mariscal'!O28 -> 0.17970568 | T28: ='Los Chillos'!O28 -> 0.57719065 | U28: ='Manuela Sáenz'!O28 -> 0.087969885 | V28: =Quitumbe!O28 -> 6.0622627e-05 | W28: =Tumbaco!O28 -> 1.0511481e-10
A29: CC_6 | B29: Venta de drogas en espacio público | C29: =Calderón!K29 -> -8.3886235 | D29: ='Choco Andino'!K29 -> 5.5150445 | E29: ='Eloy Alfaro'!K29 -> 0.74788285 | F29: ='Eugenio Espejo'!K29 -> -4.466328 | G29: ='La Delicia'!K29 -> -1.8037115 | H29: ='La Mariscal'!K29 -> -22.732986 | I29: ='Los Chillos'!K29 -> 4.8692746 | J29: ='Manuela Sáenz'!K29 -> 7.4339778 | K29: =Quitumbe!K29 -> -13.780107 | L29: =Tumbaco!K29 -> 21.586539 | N29: =Calderón!O29 -> 0.050887583 | O29: ='Choco Andino'!O29 -> 0.27838123 | P29: ='Eloy Alfaro'!O29 -> 0.85757044 | Q29: ='Eugenio Espejo'!O29 -> 0.29391406 | R29: ='La Delicia'!O29 -> 0.70000168 | S29: ='La Mariscal'!O29 -> 0.00010586479 | T29: ='Los Chillos'!O29 -> 0.16845052 | U29: ='Manuela Sáenz'!O29 -> 0.069242565 | V29: =Quitumbe!O29 -> 0.0061539107 | W29: =Tumbaco!O29 -> 9.7262798e-10
A30: CC_7 | B30: Calles sin iluminación | C30: =Calderón!K30 -> -3.4951164 | D30: ='Choco Andino'!K30 -> -6.6311495 | E30: ='Eloy Alfaro'!K30 -> -3.0854553 | F30: ='Eugenio Espejo'!K30 -> -0.58185421 | G30: ='La Delicia'!K30 -> 4.393283 | H30: ='La Mariscal'!K30 -> -7.7169948 | I30: ='Los Chillos'!K30 -> 1.5853104 | J30: ='Manuela Sáenz'!K30 -> 0.47189879 | K30: =Quitumbe!K30 -> 8.0587696 | L30: =Tumbaco!K30 -> 0.12443236 | N30: =Calderón!O30 -> 0.38614028 | O30: ='Choco Andino'!O30 -> 0.26684084 | P30: ='Eloy Alfaro'!O30 -> 0.42033948 | Q30: ='Eugenio Espejo'!O30 -> 0.88684777 | R30: ='La Delicia'!O30 -> 0.31751863 | S30: ='La Mariscal'!O30 -> 0.15067558 | T30: ='Los Chillos'!O30 -> 0.74060176 | U30: ='Manuela Sáenz'!O30 -> 0.90174311 | V30: =Quitumbe!O30 -> 0.084578612 | W30: =Tumbaco!O30 -> 0.97417924
A31: CC_8 | B31: Apropiación de viviendas por grupos delictivos | C31: =Calderón!K31 -> -0.46033128 | D31: ='Choco Andino'!K31 -> 4.2192596 | E31: ='Eloy Alfaro'!K31 -> 0.36942167 | F31: ='Eugenio Espejo'!K31 -> -2.3837422 | G31: ='La Delicia'!K31 -> -6.3655967 | H31: ='La Mariscal'!K31 -> 6.3659068 | I31: ='Los Chillos'!K31 -> 1.2026229 | J31: ='Manuela Sáenz'!K31 -> 7.4979916 | K31: =Quitumbe!K31 -> 0.50386026 | L31: =Tumbaco!K31 -> -3.445965 | N31: =Calderón!O31 -> 0.83043271 | O31: ='Choco Andino'!O31 -> 0.15096859 | P31: ='Eloy Alfaro'!O31 -> 0.87280009 | Q31: ='Eugenio Espejo'!O31 -> 0.18328349 | R31: ='La Delicia'!O31 -> 0.107214 | S31: ='La Mariscal'!O31 -> 0.038091972 | T31: ='Los Chillos'!O31 -> 0.45350843 | U31: ='Manuela Sáenz'!O31 -> 0.00097791255 | V31: =Quitumbe!O31 -> 0.87186933 | W31: =Tumbaco!O31 -> 0.13554831
A32: CC_9 | B32: Reclutamiento de NNA | C32: =Calderón!K32 -> -4.2007476 | D32: ='Choco Andino'!K32 -> 5.1548223 | E32: ='Eloy Alfaro'!K32 -> -1.1900935 | F32: ='Eugenio Espejo'!K32 -> 0.47122213 | G32: ='La Delicia'!K32 -> 1.0404768 | H32: ='La Mariscal'!K32 -> 1.3265964 | I32: ='Los Chillos'!K32 -> 4.7606728 | J32: ='Manuela Sáenz'!K32 -> -0.96355569 | K32: =Quitumbe!K32 -> -3.0962848 | L32: =Tumbaco!K32 -> 0.080975506 | N32: =Calderón!O32 -> 0.080929541 | O32: ='Choco Andino'!O32 -> 0.0034844858 | P32: ='Eloy Alfaro'!O32 -> 0.58775481 | Q32: ='Eugenio Espejo'!O32 -> 0.78779159 | R32: ='La Delicia'!O32 -> 0.78517446 | S32: ='La Mariscal'!O32 -> 0.62298817 | T32: ='Los Chillos'!O32 -> 0.0013086863 | U32: ='Manuela Sáenz'!O32 -> 0.60435557 | V32: =Quitumbe!O32 -> 0.25418704 | W32: =Tumbaco!O32 -> 0.96763896
A33: TA_3 | B33: Vio civiles armados en el barrio | C33: =Calderón!K33 -> 2.3450761 | D33: ='Choco Andino'!K33 -> -2.4034589 | E33: ='Eloy Alfaro'!K33 -> 0.68126213 | F33: ='Eugenio Espejo'!K33 -> 3.1606395 | G33: ='La Delicia'!K33 -> 1.3043605 | H33: ='La Mariscal'!K33 -> 2.0811334 | I33: ='Los Chillos'!K33 -> -4.3464728 | J33: ='Manuela Sáenz'!K33 -> -2.9059899 | K33: =Quitumbe!K33 -> -2.4582143 | L33: =Tumbaco!K33 -> 0.20230506 | N33: =Calderón!O33 -> 0.36402077 | O33: ='Choco Andino'!O33 -> 0.52138576 | P33: ='Eloy Alfaro'!O33 -> 0.81088331 | Q33: ='Eugenio Espejo'!O33 -> 0.25799747 | R33: ='La Delicia'!O33 -> 0.7327631 | S33: ='La Mariscal'!O33 -> 0.4892346 | T33: ='Los Chillos'!O33 -> 0.5021354 | U33: ='Manuela Sáenz'!O33 -> 0.29610915 | V33: =Quitumbe!O33 -> 0.48563348 | W33: =Tumbaco!O33 -> 0.93191449
A34: D. Victimización (12 meses)
A35: VI_PERS | B35: Víctima: algún delito personal (agregado) | C35: =Calderón!K35 -> 7.6350592 | D35: ='Choco Andino'!K35 -> 5.5086431 | E35: ='Eloy Alfaro'!K35 -> -2.7481845 | F35: ='Eugenio Espejo'!K35 -> -8.9303366 | G35: ='La Delicia'!K35 -> 0.46024565 | H35: ='La Mariscal'!K35 -> -0.87737182 | I35: ='Los Chillos'!K35 -> 3.6705426 | J35: ='Manuela Sáenz'!K35 -> 5.5774074 | K35: =Quitumbe!K35 -> 1.6872826 | L35: =Tumbaco!K35 -> -2.4805462 | N35: =Calderón!O35 -> 0.035061783 | O35: ='Choco Andino'!O35 -> 0.21325169 | P35: ='Eloy Alfaro'!O35 -> 0.43958145 | Q35: ='Eugenio Espejo'!O35 -> 0.011534044 | R35: ='La Delicia'!O35 -> 0.90305631 | S35: ='La Mariscal'!O35 -> 0.86443447 | T35: ='Los Chillos'!O35 -> 0.28945022 | U35: ='Manuela Sáenz'!O35 -> 0.1144617 | V35: =Quitumbe!O35 -> 0.69906663 | W35: =Tumbaco!O35 -> 0.43402912
A36: VI_HOG | B36: Víctima: algún delito contra el hogar (agregado) | C36: =Calderón!K36 -> 4.0738835 | D36: ='Choco Andino'!K36 -> -2.1398361 | E36: ='Eloy Alfaro'!K36 -> 3.6360826 | F36: ='Eugenio Espejo'!K36 -> -1.3627433 | G36: ='La Delicia'!K36 -> -4.9594064 | H36: ='La Mariscal'!K36 -> -2.7395291 | I36: ='Los Chillos'!K36 -> 6.9989623 | J36: ='Manuela Sáenz'!K36 -> 2.093705 | K36: =Quitumbe!K36 -> -4.3243564 | L36: =Tumbaco!K36 -> -3.5160987 | N36: =Calderón!O36 -> 0.16634734 | O36: ='Choco Andino'!O36 -> 0.59237863 | P36: ='Eloy Alfaro'!O36 -> 0.19507739 | Q36: ='Eugenio Espejo'!O36 -> 0.64863771 | R36: ='La Delicia'!O36 -> 0.20950192 | S36: ='La Mariscal'!O36 -> 0.5308207 | T36: ='Los Chillos'!O36 -> 0.0055813476 | U36: ='Manuela Sáenz'!O36 -> 0.48493173 | V36: =Quitumbe!O36 -> 0.19294043 | W36: =Tumbaco!O36 -> 0.17826482
A37: VI_6 | B37: Víctima: Robo con violencia o amenaza | C37: =Calderón!K37 -> -0.050246714 | D37: ='Choco Andino'!K37 -> 0.21375822 | E37: ='Eloy Alfaro'!K37 -> 0.5900871 | F37: ='Eugenio Espejo'!K37 -> -2.3185453 | G37: ='La Delicia'!K37 -> -2.0293432 | H37: ='La Mariscal'!K37 -> -4.696482 | I37: ='Los Chillos'!K37 -> 1.5076718 | J37: ='Manuela Sáenz'!K37 -> -0.6669882 | K37: =Quitumbe!K37 -> 3.1099705 | L37: =Tumbaco!K37 -> 0.75440424 | N37: =Calderón!O37 -> 0.98225827 | O37: ='Choco Andino'!O37 -> 0.92342077 | P37: ='Eloy Alfaro'!O37 -> 0.8106726 | Q37: ='Eugenio Espejo'!O37 -> 0.3307437 | R37: ='La Delicia'!O37 -> 0.41903845 | S37: ='La Mariscal'!O37 -> 0.24207414 | T37: ='Los Chillos'!O37 -> 0.46919842 | U37: ='Manuela Sáenz'!O37 -> 0.80138616 | V37: =Quitumbe!O37 -> 0.33099294 | W37: =Tumbaco!O37 -> 0.7318966
A38: VI_7 | B38: Víctima: Hurto (sin violencia) | C38: =Calderón!K38 -> 4.6292438 | D38: ='Choco Andino'!K38 -> 2.0138925 | E38: ='Eloy Alfaro'!K38 -> -4.2006361 | F38: ='Eugenio Espejo'!K38 -> -0.58730186 | G38: ='La Delicia'!K38 -> 1.7579995 | H38: ='La Mariscal'!K38 -> -2.9525778 | I38: ='Los Chillos'!K38 -> 4.7006195 | J38: ='Manuela Sáenz'!K38 -> 1.7146145 | K38: =Quitumbe!K38 -> 1.3592122 | L38: =Tumbaco!K38 -> -6.7204591 | N38: =Calderón!O38 -> 0.078028126 | O38: ='Choco Andino'!O38 -> 0.53315988 | P38: ='Eloy Alfaro'!O38 -> 0.084162764 | Q38: ='Eugenio Espejo'!O38 -> 0.78006441 | R38: ='La Delicia'!O38 -> 0.51022001 | S38: ='La Mariscal'!O38 -> 0.41786663 | T38: ='Los Chillos'!O38 -> 0.038008478 | U38: ='Manuela Sáenz'!O38 -> 0.40009621 | V38: =Quitumbe!O38 -> 0.68292637 | W38: =Tumbaco!O38 -> 0.0014932096
A39: VI_8 | B39: Víctima: Estafa | C39: =Calderón!K39 -> 1.1768393 | D39: ='Choco Andino'!K39 -> 3.6257323 | E39: ='Eloy Alfaro'!K39 -> 0.71668692 | F39: ='Eugenio Espejo'!K39 -> 0.66999684 | G39: ='La Delicia'!K39 -> 0.12089141 | H39: ='La Mariscal'!K39 -> -2.859424 | I39: ='Los Chillos'!K39 -> -1.0153314 | J39: ='Manuela Sáenz'!K39 -> 2.9057386 | K39: =Quitumbe!K39 -> -2.996638 | L39: =Tumbaco!K39 -> -0.98801218 | N39: =Calderón!O39 -> 0.53116666 | O39: ='Choco Andino'!O39 -> 0.048315295 | P39: ='Eloy Alfaro'!O39 -> 0.69604109 | Q39: ='Eugenio Espejo'!O39 -> 0.67536114 | R39: ='La Delicia'!O39 -> 0.95558266 | S39: ='La Mariscal'!O39 -> 0.39532278 | T39: ='Los Chillos'!O39 -> 0.54115463 | U39: ='Manuela Sáenz'!O39 -> 0.10021673 | V39: =Quitumbe!O39 -> 0.26075077 | W39: =Tumbaco!O39 -> 0.45359847
A40: VI_9 | B40: Víctima: Fraude bancario | C40: =Calderón!K40 -> -0.45665061 | D40: ='Choco Andino'!K40 -> -0.016419985 | E40: ='Eloy Alfaro'!K40 -> -0.0095462084 | F40: ='Eugenio Espejo'!K40 -> -2.5757167 | G40: ='La Delicia'!K40 -> 3.1740796 | H40: ='La Mariscal'!K40 -> 3.6904972 | I40: ='Los Chillos'!K40 -> 1.0429682 | J40: ='Manuela Sáenz'!K40 -> 1.7285409 | K40: =Quitumbe!K40 -> -0.71274521 | L40: =Tumbaco!K40 -> -3.3316808 | N40: =Calderón!O40 -> 0.76581006 | O40: ='Choco Andino'!O40 -> 0.99407545 | P40: ='Eloy Alfaro'!O40 -> 0.99439469 | Q40: ='Eugenio Espejo'!O40 -> 0.19054393 | R40: ='La Delicia'!O40 -> 0.035189661 | S40: ='La Mariscal'!O40 -> 0.0882661 | T40: ='Los Chillos'!O40 -> 0.50821164 | U40: ='Manuela Sáenz'!O40 -> 0.29128497 | V40: =Quitumbe!O40 -> 0.71666996 | W40: =Tumbaco!O40 -> 0.01836549
A41: VI_11 | B41: Víctima: Agresión física por desconocido | C41: =Calderón!K41 -> -3.2247986 | D41: ='Choco Andino'!K41 -> -0.53865329 | E41: ='Eloy Alfaro'!K41 -> 0.74656009 | F41: ='Eugenio Espejo'!K41 -> -1.8886085 | G41: ='La Delicia'!K41 -> 1.6644595 | H41: ='La Mariscal'!K41 -> 1.5367754 | I41: ='Los Chillos'!K41 -> -0.97499758 | J41: ='Manuela Sáenz'!K41 -> 2.4042978 | K41: =Quitumbe!K41 -> 0.0095653217 | L41: =Tumbaco!K41 -> 0.16883799 | N41: =Calderón!O41 -> 0.048498179 | O41: ='Choco Andino'!O41 -> 0.63935827 | P41: ='Eloy Alfaro'!O41 -> 0.64303943 | Q41: ='Eugenio Espejo'!O41 -> 0.059063339 | R41: ='La Delicia'!O41 -> 0.2155912 | S41: ='La Mariscal'!O41 -> 0.44960601 | T41: ='Los Chillos'!O41 -> 0.42443431 | U41: ='Manuela Sáenz'!O41 -> 0.12642004 | V41: =Quitumbe!O41 -> 0.99599761 | W41: =Tumbaco!O41 -> 0.86571791
...

Sheet Calderón
A1: Calderón vs. resto del DMQ: cambio 2023-2024 → 2025-2026
A2: Proporciones ponderadas (peso_az_estrato). DiD = cambio AZ − cambio resto. EE robusto HC1. El signo describe la dirección del indicador, sin valoración.
A4: Bloque | B4: Indicador | C4: Código | D4: Base | E4: AZ 2023 | F4: AZ 2025 | G4: Resto 2023 | H4: Resto 2025 | I4: Cambio AZ (pp) | J4: Cambio resto (pp) | K4: DiD (pp) | L4: EE (pp) | M4: IC95 inf (pp) | N4: IC95 sup (pp) | O4: Valor p | P4: Sig. | Q4: n AZ 2023 | R4: n AZ 2025 | S4: Advertencia
A5: A. Percepción de inseguridad
A6: A. Percepción de inseguridad | B6: % se siente inseguro: Alrededor de su casa | C6: PSC_1 | D6: Excluye "No aplica" | E6: 0.69878144 | F6: 0.63439523 | G6: 0.54468009 | H6: 0.55089891 | I6: =(F6-E6)*100 -> -6.4386209 | J6: =(H6-G6)*100 -> 0.62188263 | K6: =I6-J6 -> -7.0605035 | L6: 3.7668243 | M6: =K6-1.96*L6 -> -14.443479 | N6: =K6+1.96*L6 -> 0.32247204 | O6: =2*(1-NORMSDIST(ABS(K6/L6))) -> 0.060876479 | P6: =IF(O6<0.01,"**",IF(O6<0.05,"*","")) | Q6: 624 | R6: 413
A7: A. Percepción de inseguridad | B7: % se siente inseguro: En su barrio | C7: PSC_2 | D7: Excluye "No aplica" | E7: 0.75041322 | F7: 0.77503649 | G7: 0.62596459 | H7: 0.67621073 | I7: =(F7-E7)*100 -> 2.4623274 | J7: =(H7-G7)*100 -> 5.024614 | K7: =I7-J7 -> -2.5622867 | L7: 3.4996818 | M7: =K7-1.96*L7 -> -9.421663 | N7: =K7+1.96*L7 -> 4.2970897 | O7: =2*(1-NORMSDIST(ABS(K7/L7))) -> 0.46407796 | P7: =IF(O7<0.01,"**",IF(O7<0.05,"*","")) | Q7: 625 | R7: 414
A8: A. Percepción de inseguridad | B8: % se siente inseguro: Cerca de centros educativos | C8: PSC_4 | D8: Excluye "No aplica" | E8: 0.69524979 | F8: 0.67190303 | G8: 0.59496088 | H8: 0.55620806 | I8: =(F8-E8)*100 -> -2.3346759 | J8: =(H8-G8)*100 -> -3.8752822 | K8: =I8-J8 -> 1.5406063 | L8: 3.9589228 | M8: =K8-1.96*L8 -> -6.2188823 | N8: =K8+1.96*L8 -> 9.3000949 | O8: =2*(1-NORMSDIST(ABS(K8/L8))) -> 0.69716678 | P8: =IF(O8<0.01,"**",IF(O8<0.05,"*","")) | Q8: 573 | R8: 369
A9: A. Percepción de inseguridad | B9: % se siente inseguro: Mercados y ferias | C9: PSC_5 | D9: Excluye "No aplica" | E9: 0.80508047 | F9: 0.69828682 | G9: 0.76576669 | H9: 0.72686349 | I9: =(F9-E9)*100 -> -10.679364 | J9: =(H9-G9)*100 -> -3.8903201 | K9: =I9-J9 -> -6.7890444 | L9: 3.5113577 | M9: =K9-1.96*L9 -> -13.671305 | N9: =K9+1.96*L9 -> 0.093216736 | O9: =2*(1-NORMSDIST(ABS(K9/L9))) -> 0.053180443 | P9: =IF(O9<0.01,"**",IF(O9<0.05,"*","")) | Q9: 599 | R9: 387
A10: A. Percepción de inseguridad | B10: % se siente inseguro: Cajeros en vía pública | C10: PSC_6 | D10: Excluye "No aplica" | E10: 0.82839888 | F10: 0.79007935 | G10: 0.79021802 | H10: 0.79169736 | I10: =(F10-E10)*100 -> -3.8319528 | J10: =(H10-G10)*100 -> 0.14793375 | K10: =I10-J10 -> -3.9798866 | L10: 3.6553531 | M10: =K10-1.96*L10 -> -11.144379 | N10: =K10+1.96*L10 -> 3.1846055 | O10: =2*(1-NORMSDIST(ABS(K10/L10))) -> 0.27624956 | P10: =IF(O10<0.01,"**",IF(O10<0.05,"*","")) | Q10: 571 | R10: 328
A11: A. Percepción de inseguridad | B11: % se siente inseguro: Espacios públicos de la ciudad | C11: PSC_7 | D11: Excluye "No aplica" | E11: 0.82105543 | F11: 0.81602891 | G11: 0.79516141 | H11: 0.7807139 | I11: =(F11-E11)*100 -> -0.50265145 | J11: =(H11-G11)*100 -> -1.4447506 | K11: =I11-J11 -> 0.9420992 | L11: 3.3537071 | M11: =K11-1.96*L11 -> -5.6311667 | N11: =K11+1.96*L11 -> 7.5153651 | O11: =2*(1-NORMSDIST(ABS(K11/L11))) -> 0.7787773 | P11: =IF(O11<0.01,"**",IF(O11<0.05,"*","")) | Q11: 616 | R11: 407
A12: A. Percepción de inseguridad | B12: % se siente inseguro: Metro de Quito | C12: PSC_8 | D12: Excluye "No aplica" | E12: 0.42173808 | F12: 0.21569942 | G12: 0.27724954 | H12: 0.14951388 | I12: =(F12-E12)*100 -> -20.603866 | J12: =(H12-G12)*100 -> -12.773566 | K12: =I12-J12 -> -7.8302994 | L12: 4.1108916 | M12: =K12-1.96*L12 -> -15.887647 | N12: =K12+1.96*L12 -> 0.22704816 | O12: =2*(1-NORMSDIST(ABS(K12/L12))) -> 0.05681009 | P12: =IF(O12<0.01,"**",IF(O12<0.05,"*","")) | Q12: 485 | R12: 311
A13: A. Percepción de inseguridad | B13: % se siente inseguro: Trole, Ecovía, corredores | C13: PSC_9 | D13: Excluye "No aplica" | E13: 0.89463351 | F13: 0.79743695 | G13: 0.84810464 | H13: 0.7908837 | I13: =(F13-E13)*100 -> -9.719656 | J13: =(H13-G13)*100 -> -5.7220934 | K13: =I13-J13 -> -3.9975626 | L13: 2.8116132 | M13: =K13-1.96*L13 -> -9.5083246 | N13: =K13+1.96*L13 -> 1.5131993 | O13: =2*(1-NORMSDIST(ABS(K13/L13))) -> 0.15508319 | P13: =IF(O13<0.01,"**",IF(O13<0.05,"*","")) | Q13: 585 | R13: 375
A14: A. Percepción de inseguridad | B14: % se siente inseguro: Taxis amarillos | C14: PSC_11 | D14: Excluye "No aplica" | E14: 0.74673776 | F14: 0.52337421 | G14: 0.68089818 | H14: 0.51812123 | I14: =(F14-E14)*100 -> -22.336355 | J14: =(H14-G14)*100 -> -16.277695 | K14: =I14-J14 -> -6.0586596 | L14: 3.975732 | M14: =K14-1.96*L14 -> -13.851094 | N14: =K14+1.96*L14 -> 1.7337751 | O14: =2*(1-NORMSDIST(ABS(K14/L14))) -> 0.12753108 | P14: =IF(O14<0.01,"**",IF(O14<0.05,"*","")) | Q14: 562 | R14: 363
A15: A. Percepción de inseguridad | B15: % se siente inseguro: Transporte por aplicaciones | C15: PSC_12 | D15: Excluye "No aplica" | E15: 0.68827145 | F15: 0.41791368 | G15: 0.57779933 | H15: 0.37836996 | I15: =(F15-E15)*100 -> -27.035778 | J15: =(H15-G15)*100 -> -19.942937 | K15: =I15-J15 -> -7.0928404 | L15: 4.4322775 | M15: =K15-1.96*L15 -> -15.780104 | N15: =K15+1.96*L15 -> 1.5944236 | O15: =2*(1-NORMSDIST(ABS(K15/L15))) -> 0.10953872 | P15: =IF(O15<0.01,"**",IF(O15<0.05,"*","")) | Q15: 501 | R15: 335
A16: A. Percepción de inseguridad | B16: % se siente inseguro: Espectáculos públicos | C16: PSC_13 | D16: Excluye "No aplica" | E16: 0.73975123 | F16: 0.68302702 | G16: 0.69148154 | H16: 0.65129608 | I16: =(F16-E16)*100 -> -5.6724211 | J16: =(H16-G16)*100 -> -4.0185459 | K16: =I16-J16 -> -1.6538753 | L16: 4.2056151 | M16: =K16-1.96*L16 -> -9.8968809 | N16: =K16+1.96*L16 -> 6.5891303 | O16: =2*(1-NORMSDIST(ABS(K16/L16))) -> 0.69413183 | P16: =IF(O16<0.01,"**",IF(O16<0.05,"*","")) | Q16: 506 | R16: 316
A17: A. Percepción de inseguridad | B17: % se siente inseguro: Caminando solo/a en el barrio de día | C17: PSC_14 | D17: Excluye "No aplica" | E17: 0.62149613 | F17: 0.48911583 | G17: 0.48283286 | H17: 0.41590834 | I17: =(F17-E17)*100 -> -13.23803 | J17: =(H17-G17)*100 -> -6.6924518 | K17: =I17-J17 -> -6.5455782 | L17: 4.029514 | M17: =K17-1.96*L17 -> -14.443426 | N17: =K17+1.96*L17 -> 1.3522693 | O17: =2*(1-NORMSDIST(ABS(K17/L17))) -> 0.10428858 | P17: =IF(O17<0.01,"**",IF(O17<0.05,"*","")) | Q17: 613 | R17: 407
A18: A. Percepción de inseguridad | B18: % se siente inseguro: Caminando solo/a en el barrio de noche | C18: PSC_15 | D18: Excluye "No aplica" | E18: 0.90258307 | F18: 0.93207258 | G18: 0.82634782 | H18: 0.8656658 | I18: =(F18-E18)*100 -> 2.9489507 | J18: =(H18-G18)*100 -> 3.9317981 | K18: =I18-J18 -> -0.98284736 | L18: 2.3832509 | M18: =K18-1.96*L18 -> -5.6540191 | N18: =K18+1.96*L18 -> 3.6883243 | O18: =2*(1-NORMSDIST(ABS(K18/L18))) -> 0.68004789 | P18: =IF(O18<0.01,"**",IF(O18<0.05,"*","")) | Q18: 603 | R18: 398
A19: B. Evolución percibida de la delincuencia
A20: B. Evolución percibida de la delincuencia | B20: % cree que la delincuencia aumentó en su barrio | C20: PSC_16 | D20: Excluye "No aplica" | E20: 0.67715915 | F20: 0.61326219 | G20: 0.56754943 | H20: 0.50633699 | I20: =(F20-E20)*100 -> -6.3896966 | J20: =(H20-G20)*100 -> -6.1212445 | K20: =I20-J20 -> -0.26845215 | L20: 3.8193589 | M20: =K20-1.96*L20 -> -7.7543956 | N20: =K20+1.96*L20 -> 7.2174913 | O20: =2*(1-NORMSDIST(ABS(K20/L20))) -> 0.94396505 | P20: =IF(O20<0.01,"**",IF(O20<0.05,"*","")) | Q20: 618 | R20: 411
A21: B. Evolución percibida de la delincuencia | B21: % cree que la delincuencia aumentó en Quito | C21: PSC_17 | D21: Excluye "No aplica" | E21: 0.9228116 | F21: 0.92727778 | G21: 0.90588183 | H21: 0.87266384 | I21: =(F21-E21)*100 -> 0.44661841 | J21: =(H21-G21)*100 -> -3.3217995 | K21: =I21-J21 -> 3.7684179 | L21: 2.1584329 | M21: =K21-1.96*L21 -> -0.46211056 | N21: =K21+1.96*L21 -> 7.9989463 | O21: =2*(1-NORMSDIST(ABS(K21/L21))) -> 0.080827531 | P21: =IF(O21<0.01,"**",IF(O21<0.05,"*","")) | Q21: 618 | R21: 413
A22: B. Evolución percibida de la delincuencia | B22: % cree que la delincuencia aumentó en el país | C22: PSC_18 | D22: Excluye "No aplica" | E22: 0.93792626 | F22: 0.9491632 | G22: 0.95329188 | H22: 0.91147317 | I22: =(F22-E22)*100 -> 1.1236944 | J22: =(H22-G22)*100 -> -4.1818705 | K22: =I22-J22 -> 5.3055648 | L22: 1.9024846 | M22: =K22-1.96*L22 -> 1.576695 | N22: =K22+1.96*L22 -> 9.0344346 | O22: =2*(1-NORMSDIST(ABS(K22/L22))) -> 0.0052910953 | P22: =IF(O22<0.01,"**",IF(O22<0.05,"*","")) -> ** | Q22: 621 | R22: 413
A23: C. Problemas percibidos en el barrio
A24: C. Problemas percibidos en el barrio | B24: % reporta: Peleas o riñas | C24: CC_1 | D24: Excluye Ns/Nc | E24: 0.58864501 | F24: 0.49025429 | G24: 0.49601853 | H24: 0.53976703 | I24: =(F24-E24)*100 -> -9.8390718 | J24: =(H24-G24)*100 -> 4.3748497 | K24: =I24-J24 -> -14.213922 | L24: 3.964054 | M24: =K24-1.96*L24 -> -21.983467 | N24: =K24+1.96*L24 -> -6.4443756 | O24: =2*(1-NORMSDIST(ABS(K24/L24))) -> 0.00033617102 | P24: =IF(O24<0.01,"**",IF(O24<0.05,"*","")) -> ** | Q24: 614 | R24: 409
A25: C. Problemas percibidos en el barrio | B25: % reporta: Pandillas o grupos delictivos | C25: CC_2 | D25: Excluye Ns/Nc | E25: 0.56214801 | F25: 0.41593475 | G25: 0.39405102 | H25: 0.46478598 | I25: =(F25-E25)*100 -> -14.621326 | J25: =(H25-G25)*100 -> 7.0734959 | K25: =I25-J25 -> -21.694822 | L25: 4.0660189 | M25: =K25-1.96*L25 -> -29.664219 | N25: =K25+1.96*L25 -> -13.725425 | O25: =2*(1-NORMSDIST(ABS(K25/L25))) -> 9.5206972e-08 | P25: =IF(O25<0.01,"**",IF(O25<0.05,"*","")) -> ** | Q25: 602 | R25: 390
A26: C. Problemas percibidos en el barrio | B26: % reporta: Consumo de alcohol en espacio público | C26: CC_3 | D26: Excluye Ns/Nc | E26: 0.80361126 | F26: 0.7422089 | G26: 0.70958331 | H26: 0.76020996 | I26: =(F26-E26)*100 -> -6.1402362 | J26: =(H26-G26)*100 -> 5.0626656 | K26: =I26-J26 -> -11.202902 | L26: 3.2903605 | M26: =K26-1.96*L26 -> -17.652008 | N26: =K26+1.96*L26 -> -4.7537952 | O26: =2*(1-NORMSDIST(ABS(K26/L26))) -> 0.00066221199 | P26: =IF(O26<0.01,"**",IF(O26<0.05,"*","")) -> ** | Q26: 621 | R26: 407
A27: C. Problemas percibidos en el barrio | B27: % reporta: Venta clandestina de alcohol | C27: CC_4 | D27: Excluye Ns/Nc | E27: 0.52053702 | F27: 0.43803286 | G27: 0.42384907 | H27: 0.4222328 | I27: =(F27-E27)*100 -> -8.250416 | J27: =(H27-G27)*100 -> -0.16162687 | K27: =I27-J27 -> -8.0887891 | L27: 4.1622775 | M27: =K27-1.96*L27 -> -16.246853 | N27: =K27+1.96*L27 -> 0.069274753 | O27: =2*(1-NORMSDIST(ABS(K27/L27))) -> 0.051973096 | P27: =IF(O27<0.01,"**",IF(O27<0.05,"*","")) | Q27: 583 | R27: 370
A28: C. Problemas percibidos en el barrio | B28: % reporta: Consumo de drogas en espacio público | C28: CC_5 | D28: Excluye Ns/Nc | E28: 0.51624712 | F28: 0.60216519 | G28: 0.45754886 | H28: 0.541175 | I28: =(F28-E28)*100 -> 8.5918064 | J28: =(H28-G28)*100 -> 8.3626149 | K28: =I28-J28 -> 0.22919144 | L28: 4.1365722 | M28: =K28-1.96*L28 -> -7.8784901 | N28: =K28+1.96*L28 -> 8.3368729 | O28: =2*(1-NORMSDIST(ABS(K28/L28))) -> 0.95581492 | P28: =IF(O28<0.01,"**",IF(O28<0.05,"*","")) | Q28: 573 | R28: 377
A29: C. Problemas percibidos en el barrio | B29: % reporta: Venta de drogas en espacio público | C29: CC_6 | D29: Excluye Ns/Nc | E29: 0.43370467 | F29: 0.40350783 | G29: 0.32130828 | H29: 0.37499767 | I29: =(F29-E29)*100 -> -3.0196842 | J29: =(H29-G29)*100 -> 5.3689393 | K29: =I29-J29 -> -8.3886235 | L29: 4.2965117 | M29: =K29-1.96*L29 -> -16.809786 | N29: =K29+1.96*L29 -> 0.032539391 | O29: =2*(1-NORMSDIST(ABS(K29/L29))) -> 0.050887583 | P29: =IF(O29<0.01,"**",IF(O29<0.05,"*","")) | Q29: 561 | R29: 337
A30: C. Problemas percibidos en el barrio | B30: % reporta: Calles sin iluminación | C30: CC_7 | D30: Excluye Ns/Nc | E30: 0.45821619 | F30: 0.39973246 | G30: 0.37739934 | H30: 0.35386677 | I30: =(F30-E30)*100 -> -5.8483732 | J30: =(H30-G30)*100 -> -2.3532568 | K30: =I30-J30 -> -3.4951164 | L30: 4.0329591 | M30: =K30-1.96*L30 -> -11.399716 | N30: =K30+1.96*L30 -> 4.4094834 | O30: =2*(1-NORMSDIST(ABS(K30/L30))) -> 0.38614028 | P30: =IF(O30<0.01,"**",IF(O30<0.05,"*","")) | Q30: 618 | R30: 411
A31: C. Problemas percibidos en el barrio | B31: % reporta: Apropiación de viviendas por grupos delictivos | C31: CC_8 | D31: Excluye Ns/Nc | E31: 0.071152793 | F31: 0.094611196 | G31: 0.07889576 | H31: 0.10695748 | I31: =(F31-E31)*100 -> 2.3458404 | J31: =(H31-G31)*100 -> 2.8061716 | K31: =I31-J31 -> -0.46033128 | L31: 2.1496078 | M31: =K31-1.96*L31 -> -4.6735625 | N31: =K31+1.96*L31 -> 3.7529 | O31: =2*(1-NORMSDIST(ABS(K31/L31))) -> 0.83043271 | P31: =IF(O31<0.01,"**",IF(O31<0.05,"*","")) | Q31: 599 | R31: 391
A32: C. Problemas percibidos en el barrio | B32: % reporta: Reclutamiento de NNA | C32: CC_9 | D32: Excluye Ns/Nc | E32: 0.099910782 | F32: 0.050879899 | G32: 0.074822857 | H32: 0.067799451 | I32: =(F32-E32)*100 -> -4.9030883 | J32: =(H32-G32)*100 -> -0.70234062 | K32: =I32-J32 -> -4.2007476 | L32: 2.4068667 | M32: =K32-1.96*L32 -> -8.9182064 | N32: =K32+1.96*L32 -> 0.5167111 | O32: =2*(1-NORMSDIST(ABS(K32/L32))) -> 0.080929541 | P32: =IF(O32<0.01,"**",IF(O32<0.05,"*","")) | Q32: 591 | R32: 374
A33: C. Problemas percibidos en el barrio | B33: % vio civiles armados en su barrio | C33: TA_3 | D33: Excluye Ns/Nc | E33: 0.12227748 | F33: 0.11192662 | G33: 0.12662911 | H33: 0.092827495 | I33: =(F33-E33)*100 -> -1.0350858 | J33: =(H33-G33)*100 -> -3.3801618 | K33: =I33-J33 -> 2.3450761 | L33: 2.5834504 | M33: =K33-1.96*L33 -> -2.7184868 | N33: =K33+1.96*L33 -> 7.408639 | O33: =2*(1-NORMSDIST(ABS(K33/L33))) -> 0.36402077 | P33: =IF(O33<0.01,"**",IF(O33<0.05,"*","")) | Q33: 610 | R33: 412
A34: D. Victimización (12 meses)
A35: D. Victimización (12 meses) | B35: % víctima de al menos un delito personal (robo, hurto, estafa, fraude, agresión, amenaza, extorsión) | C35: VI_PERS | D35: Todos los encuestados | E35: 0.24991808 | F35: 0.37211763 | G35: 0.23957534 | H35: 0.2854243 | I35: =(F35-E35)*100 -> 12.219955 | J35: =(H35-G35)*100 -> 4.584896 | K35: =I35-J35 -> 7.6350592 | L35: 3.6225561 | M35: =K35-1.96*L35 -> 0.53484916 | N35: =K35+1.96*L35 -> 14.735269 | O35: =2*(1-NORMSDIST(ABS(K35/L35))) -> 0.035061783 | P35: =IF(O35<0.01,"**",IF(O35<0.05,"*","")) -> * | Q35: 625 | R35: 414
A36: D. Victimización (12 meses) | B36: % hogares con al menos un delito contra el hogar (vivienda, vehículo, moto, autopartes, negocio, secuestro) | C36: VI_HOG | D36: Todos los hogares; ítems filtrados = 0 si no aplica | E36: 0.14745707 | F36: 0.21446293 | G36: 0.14319932 | H36: 0.16946635 | I36: =(F36-E36)*100 -> 6.7005865 | J36: =(H36-G36)*100 -> 2.626703 | K36: =I36-J36 -> 4.0738835 | L36: 2.9434803 | M36: =K36-1.96*L36 -> -1.6953378 | N36: =K36+1.96*L36 -> 9.8431048 | O36: =2*(1-NORMSDIST(ABS(K36/L36))) -> 0.16634734 | P36: =IF(O36<0.01,"**",IF(O36<0.05,"*","")) | Q36: 625 | R36: 414
A37: D. Victimización (12 meses) | B37: % víctima: Robo con violencia o amenaza | C37: VI_6 | D37: Todos los encuestados | E37: 0.086729947 | F37: 0.12098657 | G37: 0.09510615 | H37: 0.12986524 | I37: =(F37-E37)*100 -> 3.4256624 | J37: =(H37-G37)*100 -> 3.4759091 | K37: =I37-J37 -> -0.050246714 | L37: 2.2595194 | M37: =K37-1.96*L37 -> -4.4789048 | N37: =K37+1.96*L37 -> 4.3784113 | O37: =2*(1-NORMSDIST(ABS(K37/L37))) -> 0.98225827 | P37: =IF(O37<0.01,"**",IF(O37<0.05,"*","")) | Q37: 625 | R37: 414
A38: D. Victimización (12 meses) | B38: % víctima: Hurto (sin violencia) | C38: VI_7 | D38: Todos los encuestados | E38: 0.080587534 | F38: 0.15706363 | G38: 0.085990528 | H38: 0.11617419 | I38: =(F38-E38)*100 -> 7.6476095 | J38: =(H38-G38)*100 -> 3.0183658 | K38: =I38-J38 -> 4.6292438 | L38: 2.6269033 | M38: =K38-1.96*L38 -> -0.51948658 | N38: =K38+1.96*L38 -> 9.7779742 | O38: =2*(1-NORMSDIST(ABS(K38/L38))) -> 0.078028126 | P38: =IF(O38<0.01,"**",IF(O38<0.05,"*","")) | Q38: 625 | R38: 414
A39: D. Victimización (12 meses) | B39: % víctima: Estafa | C39: VI_8 | D39: Todos los encuestados | E39: 0.054848613 | F39: 0.077211034 | G39: 0.053258724 | H39: 0.063852752 | I39: =(F39-E39)*100 -> 2.2362421 | J39: =(H39-G39)*100 -> 1.0594028 | K39: =I39-J39 -> 1.1768393 | L39: 1.8792563 | M39: =K39-1.96*L39 -> -2.506503 | N39: =K39+1.96*L39 -> 4.8601816 | O39: =2*(1-NORMSDIST(ABS(K39/L39))) -> 0.53116666 | P39: =IF(O39<0.01,"**",IF(O39<0.05,"*","")) | Q39: 625 | R39: 414
A40: D. Victimización (12 meses) | B40: % víctima: Fraude bancario | C40: VI_9 | D40: Todos los encuestados | E40: 0.037461634 | F40: 0.048285172 | G40: 0.030587634 | H40: 0.045977678 | I40: =(F40-E40)*100 -> 1.0823538 | J40: =(H40-G40)*100 -> 1.5390044 | K40: =I40-J40 -> -0.45665061 | L40: 1.5331051 | M40: =K40-1.96*L40 -> -3.4615367 | N40: =K40+1.96*L40 -> 2.5482354 | O40: =2*(1-NORMSDIST(ABS(K40/L40))) -> 0.76581006 | P40: =IF(O40<0.01,"**",IF(O40<0.05,"*","")) | Q40: 625 | R40: 414
A41: D. Victimización (12 meses) | B41: % víctima: Agresión física por desconocido | C41: VI_11 | D41: Todos los encuestados | E41: 0.05424312 | F41: 0.033749271 | G41: 0.027424416 | H41: 0.039178553 | I41: =(F41-E41)*100 -> -2.0493849 | J41: =(H41-G41)*100 -> 1.1754137 | K41: =I41-J41 -> -3.2247986 | L41: 1.6344836 | M41: =K41-1.96*L41 -> -6.4283865 | N41: =K41+1.96*L41 -> -0.021210748 | O41: =2*(1-NORMSDIST(ABS(K41/L41))) -> 0.048498179 | P41: =IF(O41<0.01,"**",IF(O41<0.05,"*","")) -> * | Q41: 625 | R41: 414
...

Sheet Choco Andino
A1: Choco Andino vs. resto del DMQ: cambio 2023-2024 → 2025-2026
A2: Proporciones ponderadas (peso_az_estrato). DiD = cambio AZ − cambio resto. EE robusto HC1. El signo describe la dirección del indicador, sin valoración.
A4: Bloque | B4: Indicador | C4: Código | D4: Base | E4: AZ 2023 | F4: AZ 2025 | G4: Resto 2023 | H4: Resto 2025 | I4: Cambio AZ (pp) | J4: Cambio resto (pp) | K4: DiD (pp) | L4: EE (pp) | M4: IC95 inf (pp) | N4: IC95 sup (pp) | O4: Valor p | P4: Sig. | Q4: n AZ 2023 | R4: n AZ 2025 | S4: Advertencia
A5: A. Percepción de inseguridad
A6: A. Percepción de inseguridad | B6: % se siente inseguro: Alrededor de su casa | C6: PSC_1 | D6: Excluye "No aplica" | E6: 0.27140731 | F6: 0.2565606 | G6: 0.56656689 | H6: 0.5578843 | I6: =(F6-E6)*100 -> -1.4846707 | J6: =(H6-G6)*100 -> -0.86825907 | K6: =I6-J6 -> -0.6164116 | L6: 5.3683136 | M6: =K6-1.96*L6 -> -11.138306 | N6: =K6+1.96*L6 -> 9.905483 | O6: =2*(1-NORMSDIST(ABS(K6/L6))) -> 0.90858457 | P6: =IF(O6<0.01,"**",IF(O6<0.05,"*","")) | Q6: 215 | R6: 270
A7: A. Percepción de inseguridad | B7: % se siente inseguro: En su barrio | C7: PSC_2 | D7: Excluye "No aplica" | E7: 0.28293562 | F7: 0.3320059 | G7: 0.64506067 | H7: 0.68449043 | I7: =(F7-E7)*100 -> 4.9070282 | J7: =(H7-G7)*100 -> 3.9429763 | K7: =I7-J7 -> 0.96405189 | L7: 5.5744869 | M7: =K7-1.96*L7 -> -9.9619424 | N7: =K7+1.96*L7 -> 11.890046 | O7: =2*(1-NORMSDIST(ABS(K7/L7))) -> 0.86269857 | P7: =IF(O7<0.01,"**",IF(O7<0.05,"*","")) | Q7: 214 | R7: 270
A8: A. Percepción de inseguridad | B8: % se siente inseguro: Cerca de centros educativos | C8: PSC_4 | D8: Excluye "No aplica" | E8: 0.32514443 | F8: 0.24281305 | G8: 0.61020605 | H8: 0.56613547 | I8: =(F8-E8)*100 -> -8.233138 | J8: =(H8-G8)*100 -> -4.4070575 | K8: =I8-J8 -> -3.8260806 | L8: 6.0058291 | M8: =K8-1.96*L8 -> -15.597506 | N8: =K8+1.96*L8 -> 7.9453446 | O8: =2*(1-NORMSDIST(ABS(K8/L8))) -> 0.524085 | P8: =IF(O8<0.01,"**",IF(O8<0.05,"*","")) | Q8: 190 | R8: 234
A9: A. Percepción de inseguridad | B9: % se siente inseguro: Mercados y ferias | C9: PSC_5 | D9: Excluye "No aplica" | E9: 0.46575904 | F9: 0.44456456 | G9: 0.77353392 | H9: 0.7259253 | I9: =(F9-E9)*100 -> -2.1194476 | J9: =(H9-G9)*100 -> -4.7608621 | K9: =I9-J9 -> 2.6414146 | L9: 6.8179953 | M9: =K9-1.96*L9 -> -10.721856 | N9: =K9+1.96*L9 -> 16.004685 | O9: =2*(1-NORMSDIST(ABS(K9/L9))) -> 0.69844673 | P9: =IF(O9<0.01,"**",IF(O9<0.05,"*","")) | Q9: 156 | R9: 242
A10: A. Percepción de inseguridad | B10: % se siente inseguro: Cajeros en vía pública | C10: PSC_6 | D10: Excluye "No aplica" | E10: 0.62243791 | F10: 0.53838015 | G10: 0.79654187 | H10: 0.79250878 | I10: =(F10-E10)*100 -> -8.4057761 | J10: =(H10-G10)*100 -> -0.40330941 | K10: =I10-J10 -> -8.0024667 | L10: 7.4724541 | M10: =K10-1.96*L10 -> -22.648477 | N10: =K10+1.96*L10 -> 6.6435434 | O10: =2*(1-NORMSDIST(ABS(K10/L10))) -> 0.28420142 | P10: =IF(O10<0.01,"**",IF(O10<0.05,"*","")) | Q10: 115 | R10: 212
A11: A. Percepción de inseguridad | B11: % se siente inseguro: Espacios públicos de la ciudad | C11: PSC_7 | D11: Excluye "No aplica" | E11: 0.49973041 | F11: 0.46792297 | G11: 0.80154935 | H11: 0.78443083 | I11: =(F11-E11)*100 -> -3.1807436 | J11: =(H11-G11)*100 -> -1.7118526 | K11: =I11-J11 -> -1.468891 | L11: 6.1764856 | M11: =K11-1.96*L11 -> -13.574803 | N11: =K11+1.96*L11 -> 10.637021 | O11: =2*(1-NORMSDIST(ABS(K11/L11))) -> 0.81202081 | P11: =IF(O11<0.01,"**",IF(O11<0.05,"*","")) | Q11: 192 | R11: 265
A12: A. Percepción de inseguridad | B12: % se siente inseguro: Metro de Quito | C12: PSC_8 | D12: Excluye "No aplica" | E12: 0.49225083 | F12: 0.23442775 | G12: 0.29424782 | H12: 0.15382302 | I12: =(F12-E12)*100 -> -25.782308 | J12: =(H12-G12)*100 -> -14.04248 | K12: =I12-J12 -> -11.739828 | L12: 8.1387601 | M12: =K12-1.96*L12 -> -27.691798 | N12: =K12+1.96*L12 -> 4.2121421 | O12: =2*(1-NORMSDIST(ABS(K12/L12))) -> 0.14917293 | P12: =IF(O12<0.01,"**",IF(O12<0.05,"*","")) | Q12: 89 | R12: 156
A13: A. Percepción de inseguridad | B13: % se siente inseguro: Trole, Ecovía, corredores | C13: PSC_9 | D13: Excluye "No aplica" | E13: 0.64610933 | F13: 0.79242717 | G13: 0.85602689 | H13: 0.79133824 | I13: =(F13-E13)*100 -> 14.631784 | J13: =(H13-G13)*100 -> -6.4688655 | K13: =I13-J13 -> 21.100649 | L13: 6.0063265 | M13: =K13-1.96*L13 -> 9.3282493 | N13: =K13+1.96*L13 -> 32.873049 | O13: =2*(1-NORMSDIST(ABS(K13/L13))) -> 0.00044295971 | P13: =IF(O13<0.01,"**",IF(O13<0.05,"*","")) -> ** | Q13: 173 | R13: 218
A14: A. Percepción de inseguridad | B14: % se siente inseguro: Taxis amarillos | C14: PSC_11 | D14: Excluye "No aplica" | E14: 0.63101165 | F14: 0.46185655 | G14: 0.68958466 | H14: 0.51870356 | I14: =(F14-E14)*100 -> -16.91551 | J14: =(H14-G14)*100 -> -17.088111 | K14: =I14-J14 -> 0.17260022 | L14: 6.8970638 | M14: =K14-1.96*L14 -> -13.345645 | N14: =K14+1.96*L14 -> 13.690845 | O14: =2*(1-NORMSDIST(ABS(K14/L14))) -> 0.98003488 | P14: =IF(O14<0.01,"**",IF(O14<0.05,"*","")) | Q14: 136 | R14: 237
A15: A. Percepción de inseguridad | B15: % se siente inseguro: Transporte por aplicaciones | C15: PSC_12 | D15: Excluye "No aplica" | E15: 0.70891493 | F15: 0.39075998 | G15: 0.59055214 | H15: 0.38116255 | I15: =(F15-E15)*100 -> -31.815495 | J15: =(H15-G15)*100 -> -20.938958 | K15: =I15-J15 -> -10.876536 | L15: 7.8783758 | M15: =K15-1.96*L15 -> -26.318153 | N15: =K15+1.96*L15 -> 4.56508 | O15: =2*(1-NORMSDIST(ABS(K15/L15))) -> 0.16741562 | P15: =IF(O15<0.01,"**",IF(O15<0.05,"*","")) | Q15: 84 | R15: 165
A16: A. Percepción de inseguridad | B16: % se siente inseguro: Espectáculos públicos | C16: PSC_13 | D16: Excluye "No aplica" | E16: 0.48491457 | F16: 0.53274647 | G16: 0.69957537 | H16: 0.65413261 | I16: =(F16-E16)*100 -> 4.7831901 | J16: =(H16-G16)*100 -> -4.544276 | K16: =I16-J16 -> 9.3274662 | L16: 7.3806941 | M16: =K16-1.96*L16 -> -5.1386942 | N16: =K16+1.96*L16 -> 23.793627 | O16: =2*(1-NORMSDIST(ABS(K16/L16))) -> 0.20631422 | P16: =IF(O16<0.01,"**",IF(O16<0.05,"*","")) | Q16: 131 | R16: 207
A17: A. Percepción de inseguridad | B17: % se siente inseguro: Caminando solo/a en el barrio de día | C17: PSC_14 | D17: Excluye "No aplica" | E17: 0.16624535 | F17: 0.094144481 | G17: 0.50362535 | H17: 0.42225935 | I17: =(F17-E17)*100 -> -7.2100871 | J17: =(H17-G17)*100 -> -8.1366004 | K17: =I17-J17 -> 0.92651335 | L17: 4.2960367 | M17: =K17-1.96*L17 -> -7.4937185 | N17: =K17+1.96*L17 -> 9.3467452 | O17: =2*(1-NORMSDIST(ABS(K17/L17))) -> 0.82924732 | P17: =IF(O17<0.01,"**",IF(O17<0.05,"*","")) | Q17: 214 | R17: 269
A18: A. Percepción de inseguridad | B18: % se siente inseguro: Caminando solo/a en el barrio de noche | C18: PSC_15 | D18: Excluye "No aplica" | E18: 0.42567672 | F18: 0.41401404 | G18: 0.84085947 | H18: 0.87223644 | I18: =(F18-E18)*100 -> -1.1662683 | J18: =(H18-G18)*100 -> 3.1376974 | K18: =I18-J18 -> -4.3039657 | L18: 6.1068679 | M18: =K18-1.96*L18 -> -16.273427 | N18: =K18+1.96*L18 -> 7.6654953 | O18: =2*(1-NORMSDIST(ABS(K18/L18))) -> 0.48095048 | P18: =IF(O18<0.01,"**",IF(O18<0.05,"*","")) | Q18: 205 | R18: 258
A19: B. Evolución percibida de la delincuencia
A20: B. Evolución percibida de la delincuencia | B20: % cree que la delincuencia aumentó en su barrio | C20: PSC_16 | D20: Excluye "No aplica" | E20: 0.24693942 | F20: 0.28244131 | G20: 0.58440327 | H20: 0.5147293 | I20: =(F20-E20)*100 -> 3.5501889 | J20: =(H20-G20)*100 -> -6.967397 | K20: =I20-J20 -> 10.517586 | L20: 5.6919793 | M20: =K20-1.96*L20 -> -0.63869355 | N20: =K20+1.96*L20 -> 21.673865 | O20: =2*(1-NORMSDIST(ABS(K20/L20))) -> 0.06463264 | P20: =IF(O20<0.01,"**",IF(O20<0.05,"*","")) | Q20: 201 | R20: 244
A21: B. Evolución percibida de la delincuencia | B21: % cree que la delincuencia aumentó en Quito | C21: PSC_17 | D21: Excluye "No aplica" | E21: 0.94466385 | F21: 0.93770166 | G21: 0.90749647 | H21: 0.87629309 | I21: =(F21-E21)*100 -> -0.69621929 | J21: =(H21-G21)*100 -> -3.1203378 | K21: =I21-J21 -> 2.4241185 | L21: 2.7583283 | M21: =K21-1.96*L21 -> -2.982205 | N21: =K21+1.96*L21 -> 7.830442 | O21: =2*(1-NORMSDIST(ABS(K21/L21))) -> 0.37949014 | P21: =IF(O21<0.01,"**",IF(O21<0.05,"*","")) | Q21: 205 | R21: 257
A22: B. Evolución percibida de la delincuencia | B22: % cree que la delincuencia aumentó en el país | C22: PSC_18 | D22: Excluye "No aplica" | E22: 0.9766962 | F22: 0.92882461 | G22: 0.95117173 | H22: 0.91406464 | I22: =(F22-E22)*100 -> -4.7871593 | J22: =(H22-G22)*100 -> -3.7107085 | K22: =I22-J22 -> -1.0764508 | L22: 2.2680139 | M22: =K22-1.96*L22 -> -5.5217581 | N22: =K22+1.96*L22 -> 3.3688565 | O22: =2*(1-NORMSDIST(ABS(K22/L22))) -> 0.63505596 | P22: =IF(O22<0.01,"**",IF(O22<0.05,"*","")) | Q22: 211 | R22: 266
A23: C. Problemas percibidos en el barrio
A24: C. Problemas percibidos en el barrio | B24: % reporta: Peleas o riñas | C24: CC_1 | D24: Excluye Ns/Nc | E24: 0.39954695 | F24: 0.45652459 | G24: 0.50818686 | H24: 0.53661356 | I24: =(F24-E24)*100 -> 5.6977641 | J24: =(H24-G24)*100 -> 2.8426703 | K24: =I24-J24 -> 2.8550937 | L24: 5.9807663 | M24: =K24-1.96*L24 -> -8.8672083 | N24: =K24+1.96*L24 -> 14.577396 | O24: =2*(1-NORMSDIST(ABS(K24/L24))) -> 0.63309209 | P24: =IF(O24<0.01,"**",IF(O24<0.05,"*","")) | Q24: 212 | R24: 267
A25: C. Problemas percibidos en el barrio | B25: % reporta: Pandillas o grupos delictivos | C25: CC_2 | D25: Excluye Ns/Nc | E25: 0.13058363 | F25: 0.2808289 | G25: 0.41714941 | H25: 0.46212377 | I25: =(F25-E25)*100 -> 15.024527 | J25: =(H25-G25)*100 -> 4.4974363 | K25: =I25-J25 -> 10.527091 | L25: 4.8776804 | M25: =K25-1.96*L25 -> 0.96683745 | N25: =K25+1.96*L25 -> 20.087345 | O25: =2*(1-NORMSDIST(ABS(K25/L25))) -> 0.030910992 | P25: =IF(O25<0.01,"**",IF(O25<0.05,"*","")) -> * | Q25: 211 | R25: 266
A26: C. Problemas percibidos en el barrio | B26: % reporta: Consumo de alcohol en espacio público | C26: CC_3 | D26: Excluye Ns/Nc | E26: 0.71120439 | F26: 0.77733492 | G26: 0.72093198 | H26: 0.75888962 | I26: =(F26-E26)*100 -> 6.6130525 | J26: =(H26-G26)*100 -> 3.7957637 | K26: =I26-J26 -> 2.8172889 | L26: 5.3556316 | M26: =K26-1.96*L26 -> -7.6797491 | N26: =K26+1.96*L26 -> 13.314327 | O26: =2*(1-NORMSDIST(ABS(K26/L26))) -> 0.5988588 | P26: =IF(O26<0.01,"**",IF(O26<0.05,"*","")) | Q26: 212 | R26: 269
A27: C. Problemas percibidos en el barrio | B27: % reporta: Venta clandestina de alcohol | C27: CC_4 | D27: Excluye Ns/Nc | E27: 0.46030178 | F27: 0.48259806 | G27: 0.43475092 | H27: 0.42308835 | I27: =(F27-E27)*100 -> 2.2296284 | J27: =(H27-G27)*100 -> -1.166257 | K27: =I27-J27 -> 3.3958854 | L27: 6.2209179 | M27: =K27-1.96*L27 -> -8.7971137 | N27: =K27+1.96*L27 -> 15.588885 | O27: =2*(1-NORMSDIST(ABS(K27/L27))) -> 0.58514724 | P27: =IF(O27<0.01,"**",IF(O27<0.05,"*","")) | Q27: 204 | R27: 255
A28: C. Problemas percibidos en el barrio | B28: % reporta: Consumo de drogas en espacio público | C28: CC_5 | D28: Excluye Ns/Nc | E28: 0.21835896 | F28: 0.40596107 | G28: 0.46706959 | H28: 0.54592696 | I28: =(F28-E28)*100 -> 18.760211 | J28: =(H28-G28)*100 -> 7.8857373 | K28: =I28-J28 -> 10.874473 | L28: 5.7492141 | M28: =K28-1.96*L28 -> -0.39398617 | N28: =K28+1.96*L28 -> 22.142933 | O28: =2*(1-NORMSDIST(ABS(K28/L28))) -> 0.058561459 | P28: =IF(O28<0.01,"**",IF(O28<0.05,"*","")) | Q28: 198 | R28: 250
A29: C. Problemas percibidos en el barrio | B29: % reporta: Venta de drogas en espacio público | C29: CC_6 | D29: Excluye Ns/Nc | E29: 0.15351821 | F29: 0.24982671 | G29: 0.33627804 | H29: 0.3774361 | I29: =(F29-E29)*100 -> 9.6308506 | J29: =(H29-G29)*100 -> 4.1158061 | K29: =I29-J29 -> 5.5150445 | L29: 5.0878533 | M29: =K29-1.96*L29 -> -4.457148 | N29: =K29+1.96*L29 -> 15.487237 | O29: =2*(1-NORMSDIST(ABS(K29/L29))) -> 0.27838123 | P29: =IF(O29<0.01,"**",IF(O29<0.05,"*","")) | Q29: 196 | R29: 236
A30: C. Problemas percibidos en el barrio | B30: % reporta: Calles sin iluminación | C30: CC_7 | D30: Excluye Ns/Nc | E30: 0.5569455 | F30: 0.46226488 | G30: 0.38503062 | H30: 0.3566615 | I30: =(F30-E30)*100 -> -9.4680618 | J30: =(H30-G30)*100 -> -2.8369123 | K30: =I30-J30 -> -6.6311495 | L30: 5.972033 | M30: =K30-1.96*L30 -> -18.336334 | N30: =K30+1.96*L30 -> 5.0740353 | O30: =2*(1-NORMSDIST(ABS(K30/L30))) -> 0.26684084 | P30: =IF(O30<0.01,"**",IF(O30<0.05,"*","")) | Q30: 213 | R30: 269
A31: C. Problemas percibidos en el barrio | B31: % reporta: Apropiación de viviendas por grupos delictivos | C31: CC_8 | D31: Excluye Ns/Nc | E31: 0.020761955 | F31: 0.090432694 | G31: 0.078660736 | H31: 0.10613888 | I31: =(F31-E31)*100 -> 6.967074 | J31: =(H31-G31)*100 -> 2.7478144 | K31: =I31-J31 -> 4.2192596 | L31: 2.9379603 | M31: =K31-1.96*L31 -> -1.5391427 | N31: =K31+1.96*L31 -> 9.9776619 | O31: =2*(1-NORMSDIST(ABS(K31/L31))) -> 0.15096859 | P31: =IF(O31<0.01,"**",IF(O31<0.05,"*","")) | Q31: 204 | R31: 266
